<?xml version="1.0" encoding="utf-8"?>
<!-- This URDF was automatically created by SolidWorks to URDF Exporter! Originally created by Stephen Brawner (brawner@gmail.com) 
     Commit Version: 1.6.0-4-g7f85cfe  Build Version: 1.6.7995.38578
     For more information, please see http://wiki.ros.org/sw_urdf_exporter -->
<robot name="e3">
  <!-- <mujoco>
    <compiler meshdir="meshes" discardvisual="false"/>
  </mujoco>
  <link name="world"></link>
  <joint name="floating_base_joint" type="floating">
    <parent link="world"/>
    <child link="pelvis_link"/>
  </joint> -->


  <link
    name="pelvis_link">
    <inertial>
      <origin
        xyz="0.000508 0.000303 0.035758"
        rpy="0 0 0" />
      <mass
        value="5.119835" />
      <inertia
        ixx="0.022863"
        ixy="0.000002"
        ixz="0.000106"
        iyy="0.019513"
        iyz="-0.000153"
        izz="0.012083" />
    </inertial>
    <visual>
      <origin
        xyz="0 0 0"
        rpy="0 0 0" />
      <geometry>
        <mesh
          filename="./meshes/pelvis.STL" />
      </geometry>
      <material
        name="">
        <color
          rgba="0.64706 0.61961 0.58824 1" />
      </material>
    </visual>
    <collision>
      <origin
        xyz="0 0 0"
        rpy="0 0 0" />
      <geometry>
        <mesh filename="meshes/pelvis.STL"/>
      </geometry>
    </collision>
  </link>

  <joint name="imu_joint" type="fixed">
    <origin rpy="0. 0. 0." xyz="0. 0. 0"/>
    <parent link="pelvis_link"/>
    <child link="imu_link"/>
  </joint>

    <!-- Imu link -->
  <link name="imu_link">
    <inertial>
      <mass value="0.01"/>
      <origin rpy="0 0 0" xyz="0 0 0"/>
      <inertia ixx="0.000001" ixy="0" ixz="0" iyy="0.000001" iyz="0" izz="0.000001"/>
    </inertial>
    <visual>
      <origin rpy="0 0 0" xyz="0 0 0"/>
      <geometry>
        <box size="0.015 0.015 0.004"/>
      </geometry>
    </visual>
    <material name="orange">
      <color rgba="255 108 10 255"/>
    </material>
  </link>

    <!-- Torso -->
  <joint name="waist_joint" type="revolute">
    <origin xyz="0 0 0.3763" rpy="0 0 0"/>
    <parent link="pelvis_link"/>
    <child link="torso_link"/>
    <axis xyz="0 0 1"/>
    <limit lower="-1.57" upper="1.57" effort="144" velocity="20"/>
  </joint>
  
  <link name="torso_link">
    <inertial>
      <origin xyz="-0.006939 -0.002038 -0.085719" rpy="0 0 0"/>
      <mass value="13.759631"/>
      <inertia ixx="0.327498" ixy="0.000705" ixz="0.001071" iyy="0.269489" iyz="-0.004427" izz="0.140454"/>
    </inertial>
    <visual>
      <origin xyz="0 0 0.0" rpy="0 0 0"/>
      <geometry>
        <mesh filename="meshes/torso_link.STL"/>
      </geometry>
      <material name="white">
        <color rgba="0.7 0.7 0.7 1"/>
      </material>
    </visual>
    <collision>
      <origin xyz="0 0 0.0" rpy="0 0 0"/>
      <geometry>
        <mesh filename="meshes/torso_link.STL"/>
      </geometry>
    </collision>
  </link>

  <link
    name="left_hip_pitch_link">
    <inertial>
      <origin  xyz="0.011949 -0.00848 -0.026594"  rpy="0 0 0" />
      <mass value="1.816901" />
      <inertia ixx="0.001651"  ixy="-0.000034"  ixz="0.000015"  iyy="0.000959"  iyz="0.000201"  izz="0.001576" />
    </inertial>
    <visual>
      <origin
        xyz="0 0 0"
        rpy="0 0 0" />
      <geometry>
        <mesh
          filename="./meshes/leg_l1_link.STL" />
      </geometry>
      <material
        name="">
        <color
          rgba="0.64706 0.61961 0.58824 1" />
      </material>
    </visual>
    <collision>
      <origin xyz="0 0 0.0" rpy="0 0 0"/>
      <geometry>
        <mesh filename="meshes/leg_l1_link.STL"/>
      </geometry>
    </collision>
  </link>
  <joint
    name="left_hip_pitch_joint"
    type="revolute">
    <origin
      xyz="0 0.1413 0"
      rpy="0 0 0" />
    <parent
      link="pelvis_link" />
    <child
      link="left_hip_pitch_link" />
    <axis
      xyz="0 1 0" />
    <limit
      lower="-2.53"
      upper="2.53"
      effort="144"
      velocity="20" />
  </joint>
  <link
    name="left_hip_roll_link">
    <inertial>
      <origin  xyz="-0.002932 0.000098 -0.097396"  rpy="0 0 0" />
      <mass  value="2.261445" />
      <inertia   ixx="0.005632" ixy="-0.000002" ixz="0.000169"  iyy="0.006378" iyz="0.000004" izz="0.004402" />
    </inertial>
    <visual>
      <origin
        xyz="0 0 0"
        rpy="0 0 0" />
      <geometry>
         
        <mesh
          filename="./meshes/leg_l2_link_144.STL" />
      </geometry>
      <material
        name="">
        <color
          rgba="0.64706 0.61961 0.58824 1" />
      </material>
    </visual>
    <!-- <collision>
      <origin
        xyz="0 0 0"
        rpy="0 1.57 0" />
      <geometry>
         <cylinder length="0.05" radius="0.06"/>
      </geometry>
    </collision> -->
    <collision>
      <origin xyz="0 0 0.0" rpy="0 0 0"/>
      <geometry>
        <mesh filename="meshes/leg_l2_link_144.STL"/>
      </geometry>
    </collision>
  </link>
  <joint
    name="left_hip_roll_joint"
    type="revolute">
    <origin
      xyz="0.0 0 -0.0285"
      rpy="0 0 0" />
    <parent
      link="left_hip_pitch_link" />
    <child
      link="left_hip_roll_link" />
    <axis
      xyz="1 0 0" />
    <limit
      lower="-0.611"
      upper="3.23"
      effort="144"
      velocity="20" />
  </joint>
  <link
    name="left_hip_yaw_link">
    <inertial>
      <origin xyz="-0.001336 -0.000844 -0.104378" rpy="0 0 0" />
      <mass value="2.233223" />
      <inertia  ixx="0.005397" ixy="-0.000015"  ixz="-0.000535" iyy="0.0057" iyz="0.000012"  izz="0.001962" />
    </inertial>
    <visual>
      <origin
        xyz="0 0 0"
        rpy="0 0 0" />
      <geometry>
        <mesh
          filename="./meshes/leg_l3_link_144.STL" />
      </geometry>
      <material
        name="">
        <color
          rgba="0.64706 0.61961 0.58824 1" />
      </material>
    </visual>
    <!-- <collision>
      <origin
        xyz="0 0 -0.05"
        rpy="0 0 0" />
      <geometry>
          <box size="0.05 0.05 0.15"/>
      </geometry>
    </collision> -->
    <collision>
      <origin xyz="0 0 0.0" rpy="0 0 0"/>
      <geometry>
        <mesh filename="meshes/leg_l3_link_144.STL"/>
      </geometry>
    </collision>
  </link>
  <joint
    name="left_hip_yaw_joint"
    type="revolute">
    <origin
      xyz="-0.0 0 -0.1458"
      rpy="0 0 0" />
    <parent
      link="left_hip_roll_link" />
    <child
      link="left_hip_yaw_link" />
    <axis
      xyz="0 0 1" />
    <limit
      lower="-1.05"
      upper="1.05"
      effort="144"
      velocity="20" />
  </joint>
  <link name="left_knee_link">
    <inertial>
      <origin  xyz="0.001004 0.001585 -0.170623"  rpy="0 0 0" />
      <mass  value="2.889750" />
      <inertia ixx="0.020628"  ixy="0.000043" ixz="0.000485"  iyy="0.021234"  iyz="-0.000475"  izz="0.002830" />
    </inertial>
    <visual>
      <origin
        xyz="0 0 0"
        rpy="0 0 0" />
      <geometry>
        <mesh
          filename="./meshes/leg_l4_link.STL" />
      </geometry>
      <material
        name="">
        <color
          rgba="0.64706 0.61961 0.58824 1" />
      </material>
    </visual>
    <collision>
      <origin
        xyz="0 0 -0.2"
        rpy="0 0 0" />
      <geometry>
          <box size="0.05 0.05 0.2"/>
      </geometry>
    </collision>
  </link>
  <joint
    name="left_knee_joint"
    type="revolute">
    <origin
      xyz="-0.008 0 -0.1317"
      rpy="0 0 0" />
    <parent
      link="left_hip_yaw_link" />
    <child
      link="left_knee_link" />
    <axis
      xyz="0 1 0" />
    <limit
      lower="-0.349"
      upper="2.355"
      effort="144"
      velocity="20" />
  </joint>

  <link
     name="left_ankle_pitch_link">
    <inertial>
      <origin  xyz="0 0 0"  rpy="0 0 0" />
      <mass  value="0.088534" />
       <!-- <inertia ixx="0.01" ixy="0" ixz="0.0" iyy="0.01" iyz="0" izz="0.01"/> -->
      <inertia
        ixx="3.0975E-05"
        ixy="0"
        ixz="0"
        iyy="3.1274E-05"
        iyz="0"
        izz="3.1681E-05" />
    </inertial>
    <visual>
      <origin
        xyz="0 0 0"
        rpy="0 0 0" />
      <geometry>
        <mesh
          filename="./meshes/leg_l5_link.STL" />
      </geometry>
      <material
        name="">
        <color
          rgba="0.64706 0.61961 0.58824 1" />
      </material>
    </visual>
  </link>
  
  <joint
    name="left_ankle_pitch_joint"
    type="revolute">
    <origin
      xyz="0 0 -0.35"
      rpy="0 0 0" />
    <parent
      link="left_knee_link" />
    <child
      link="left_ankle_pitch_link" />
    <axis
      xyz="0 1 0" />
    <limit
      lower="-0.785"
      upper="1.05"
      effort="48"
      velocity="20" />
  </joint>
  <link
    name="left_ankle_roll_link">
    <inertial>
      <origin xyz="-0.000705 1.4E-05 -0.028746"  rpy="0 0 0" />
      <mass  value="0.611" />
      <inertia ixx="0.01" ixy="0" ixz="0.0" iyy="0.01" iyz="0" izz="0.01"/>
      <!-- <inertia
        ixx="0.00105334189"
        ixy="-0.0"
        ixz="0.0"
        iyy="0.00606712875"
        iyz="0.0"
        izz="0.00646061141" /> -->
    </inertial>

    <visual>
      <origin
        xyz="0 0 0"
        rpy="0 0 0" />
      <geometry>
        <mesh
          filename="./meshes/leg_l6_link.STL" />
      </geometry>
      <material
        name="">
        <color
          rgba="0.64706 0.61961 0.58824 1" />
      </material>
    </visual>
    <collision>
      <origin rpy="0 0 0" xyz="0.01 0 -0.05"/>
      <geometry>
        <box size="0.22 0.06 0.01"/>
      </geometry>
    </collision>
     <!-- <collision>
      <origin
        xyz="0 0 0"
        rpy="0 0 0" />
      <geometry>
        <mesh
          filename="../meshes/leg_l6_link.STL" />
      </geometry>
    </collision> -->
  </link>
  <joint
    name="left_ankle_roll_joint"
    type="revolute">
    <origin
      xyz="0 0 0"
      rpy="0 0 0" />
    <parent
      link="left_ankle_pitch_link" />
    <child
      link="left_ankle_roll_link" />
    <axis
      xyz="1 0 0" />
    <limit
      lower="-0.26"
      upper="0.26"
      effort="48"
      velocity="20" />
  </joint>

  <link
   name="right_hip_pitch_link">
    <inertial>
      <origin  xyz="0.011914 0.008479 -0.026587"  rpy="0 0 0" />
      <mass value="1.816858" />
      <inertia ixx="0.001651"  ixy="0.000034"  ixz="0.000015"  iyy="0.000957"  iyz="-0.000201"  izz="0.001575" />
    </inertial>
    <visual>
      <origin
        xyz="0 0 0"
        rpy="0 0 0" />
      <geometry>
        <mesh
          filename="./meshes/leg_r1_link.STL" />
      </geometry>
      <material
        name="">
        <color
          rgba="0.64706 0.61961 0.58824 1" />
      </material>
    </visual>
    <collision>
      <origin
        xyz="0 0 0"
        rpy="0 0 0" />
      <geometry>
        <mesh
          filename="./meshes/leg_r1_link.STL" />
      </geometry>
    </collision>
  </link>
  <joint
    name="right_hip_pitch_joint"
    type="revolute">
    <origin
      xyz="0 -0.1413 0"
      rpy="0 0 0" />
    <parent
      link="pelvis_link" />
    <child
      link="right_hip_pitch_link" />
    <axis
      xyz="0 1 0" />
    <limit
      lower="-2.53"
      upper="2.53"
      effort="144"
      velocity="20" />
  </joint>
  <link
    name="right_hip_roll_link">
    <inertial>
      <origin  xyz="-0.002874 0.000215 -0.097305"  rpy="0 0 0" />
      <mass  value="2.020075" />
      <inertia   ixx="0.005648" ixy="-3E-6" ixz="0.000160"  iyy="0.006397" iyz="-0.000002" izz="0.004413" />
    </inertial>
    <visual>
      <origin
        xyz="0 0 0"
        rpy="0 0 0" />
      <geometry>
        <mesh
          filename="./meshes/leg_r2_link_144.STL" />
      </geometry>
      <material
        name="">
        <color
          rgba="0.64706 0.61961 0.58824 1" />
      </material>
    </visual>
    <!-- <collision>
      <origin
        xyz="0 0 0"
        rpy="0 1.57 0" />
      <geometry>
            <cylinder length="0.05" radius="0.06"/>
      </geometry>
    </collision> -->
    <collision>
      <origin
        xyz="0 0 0"
        rpy="0 0 0" />
      <geometry>
        <mesh
          filename="./meshes/leg_r2_link_144.STL" />
      </geometry>
    </collision>
  </link>
  <joint
    name="right_hip_roll_joint"
    type="revolute">
    <origin
      xyz="0 0 -0.0285"
      rpy="0 0 0" />
    <parent
      link="right_hip_pitch_link" />
    <child
      link="right_hip_roll_link" />
    <axis
      xyz="1 0 0" />
    <limit
      lower="-3.23"
      upper="0.611"
      effort="144"
      velocity="20" />
  </joint>
  <link
    name="right_hip_yaw_link">
    <inertial>
      <origin xyz="0.000912 0.001350 -0.104391" rpy="0 0 0" />
      <mass value="2.231719" />
      <inertia  ixx="0.005690" ixy="-0.000016"  ixz="-0.000008" iyy="0.005388" iyz="0.000535"  izz="0.001958" />
    </inertial>
    <visual>
      <origin
        xyz="0 0 0"
        rpy="0 0 0" />
      <geometry>
        <mesh
          filename="./meshes/leg_r3_link_144.STL" />
      </geometry>
      <material
        name="">
        <color
          rgba="0.64706 0.61961 0.58824 1" />
      </material>
    </visual>
    <!-- <collision>
      <origin
        xyz="0 0 -0.05"
        rpy="0 0 0" />
      <geometry>
           <box size="0.05 0.05 0.15"/>
      </geometry>
    </collision> -->
    <collision>
      <origin
        xyz="0 0 0"
        rpy="0 0 0" />
      <geometry>
        <mesh
          filename="./meshes/leg_r3_link_144.STL" />
      </geometry>
    </collision>
  </link>
  <joint
    name="right_hip_yaw_joint"
    type="revolute">
    <origin
      xyz="0 0 -0.1458"
      rpy="0 0 0" />
    <parent
      link="right_hip_roll_link" />
    <child
      link="right_hip_yaw_link" />
    <axis
      xyz="0 0 1" />
    <limit
      lower="-1.05"
      upper="1.05"
      effort="144"
      velocity="20" />
  </joint>
  <link
    name="right_knee_link">
    <inertial>
      <origin  xyz="-0.001668 -0.001457 -0.178503"  rpy="0 0 0" />
      <mass  value="2.866292" />
      <inertia ixx="0.022193"  ixy="-0.000046" ixz="-0.000519"  iyy="0.023014"  iyz="0.000295"  izz="0.002999" />
    </inertial>
    <visual>
      <origin
        xyz="0 0 0"
        rpy="0 0 0" />
      <geometry>
        <mesh
          filename="./meshes/leg_r4_link.STL" />
      </geometry>
      <material
        name="">
        <color
          rgba="0.64706 0.61961 0.58824 1" />
      </material>
    </visual>
    <collision>
      <origin
        xyz="0 0 -0.2"
        rpy="0 0 0" />
      <geometry>
          <box size="0.05 0.05 0.2"/>
      </geometry>
    </collision>
  </link>
  <joint
    name="right_knee_joint"
    type="revolute">
    <origin
      xyz="-0.008 0 -0.1317"
      rpy="0 0 0" />
    <parent
      link="right_hip_yaw_link" />
    <child
      link="right_knee_link" />
    <axis
      xyz="0 1 0" />
    <limit
      lower="-0.349"
      upper="2.355"
      effort="144"
      velocity="20" />
  </joint>

  <link name="right_ankle_pitch_link">
    <inertial>
      <origin  xyz="0 0 0"  rpy="0 0 0" />
      <mass  value="0.088534" />
      <!-- <inertia ixx="0.01" ixy="0" ixz="0" iyy="0.01" iyz="0" izz="0.01"/> -->
      <inertia
        ixx="3.0975E-05"
        ixy="0"
        ixz="0"
        iyy="3.1274E-05"
        iyz="0"
        izz="3.1274E-05" />

    </inertial>

    <visual>
      <origin
        xyz="0 0 0"
        rpy="0 0 0" />
      <geometry>
        <mesh
          filename="./meshes/leg_r5_link.STL" />
      </geometry>
      <material
        name="">
        <color
          rgba="0.64706 0.61961 0.58824 1" />
      </material>
    </visual>
  </link>
  <joint
    name="right_ankle_pitch_joint"
    type="revolute">
    <origin
      xyz="0 0 -0.35"
      rpy="0 0 0" />
    <parent
      link="right_knee_link" />
    <child
      link="right_ankle_pitch_link" />
    <axis
      xyz="0 1 0" />
    <limit
      lower="-0.785"
      upper="1.05"
      effort="48"
      velocity="20" />
  </joint>
  <link
    name="right_ankle_roll_link">
    <inertial>
      <origin xyz="-0.000705 1.4E-05 -0.028746"  rpy="0 0 0" />
      <mass  value="0.611" />
      <inertia ixx="0.01" ixy="0" ixz="0.0" iyy="0.01" iyz="0" izz="0.01"/>
      <!-- <inertia
        ixx="0.00105336111"
        ixy="0.0"
        ixz="0.0"
        iyy="0.00606728572"
        iyz="-0.0"
        izz="0.00646075577" /> -->
    </inertial>

    <visual>
      <origin
        xyz="0 0 0"
        rpy="0 0 0" />
      <geometry>
        <mesh
          filename="./meshes/leg_r6_link.STL" />
      </geometry>
      <material
        name="">
        <color
          rgba="0.64706 0.61961 0.58824 1" />
      </material>
    </visual>
    <collision>
      <origin rpy="0 0 0" xyz="0.01 0 -0.05"/>
      <geometry>
        <box size="0.22 0.06 0.01"/>
      </geometry>
    </collision>
    <!-- <collision>
      <origin
        xyz="0 0 0"
        rpy="0 0 0" />
      <geometry>
        <mesh
          filename="../meshes/leg_r6_link.STL" />
      </geometry>
    </collision> -->
  </link>
  <joint
    name="right_ankle_roll_joint"
    type="revolute">
    <origin
      xyz="0 0 0"
      rpy="0 0 0" />
    <parent
      link="right_ankle_pitch_link" />
    <child
      link="right_ankle_roll_link" />
    <axis
      xyz="1 0 0" />
    <limit
      lower="-0.26"
      upper="0.26"
      effort="48"
      velocity="20" />
  </joint>
  <link
    name="left_shoulder_pitch_link">
    <inertial>
      <origin  xyz="-0.003432 -0.009458 -0.00891"  rpy="0 0 0" />
      <mass  value="0.859213" />
      <inertia ixx="0.001249"  ixy="0.000029"  ixz="0.000022"  iyy="0.000590"  iyz="0.000026" izz="0.000975" />
    </inertial>
    <visual>
      <origin
        xyz="0 0 0"
        rpy="0 0 0" />
      <geometry>
        <mesh
          filename="meshes/arm_l1_link.STL" />
      </geometry>
      <material
        name="">
        <color
          rgba="0.64706 0.61961 0.58824 1" />
      </material>
    </visual>
    <!-- <collision>
      <origin
        xyz="0 0 0"
        rpy="0 0 0" />
      <geometry>
        <mesh
          filename="meshes/arm_l1_link.STL" />
      </geometry>
    </collision> -->
  </link>

  <joint
    name="left_shoulder_pitch_joint"
    type="revolute">
    <origin
      xyz="0 0.25799 0.0"
      rpy="0 0 0" />
    <parent
      link="torso_link" />
    <child
      link="left_shoulder_pitch_link" />
    <axis
      xyz="0 1 0" />
    <limit
      lower="-2.74"
      upper="1.96"
      effort="24"
      velocity="20" />
  </joint>

  <link
    name="left_shoulder_roll_link">
    <inertial>
      <origin xyz="0.004195 0.000475 -0.057018"  rpy="0 0 0" />
      <mass  value="0.701407" />
      <inertia  ixx="0.001561"  ixy="-0.000083"  ixz="-0.000173"  iyy="0.001606"  iyz="0.000003"  izz="0.000973" />
    </inertial>
    <visual>
      <origin
        xyz="0 0 0"
        rpy="0 0 0" />
      <geometry>
        <mesh
          filename="meshes/arm_l2_link.STL" />
      </geometry>
      <material
        name="">
        <color
          rgba="0.64706 0.61961 0.58824 1" />
      </material>
    </visual>
    <!-- <collision>
      <origin
        xyz="0 0 0"
        rpy="0 0 0" />
      <geometry>
        <mesh
          filename="meshes/arm_l2_link.STL" />
      </geometry>
    </collision> -->
  </link>

  <joint
    name="left_shoulder_roll_joint"
    type="revolute">
    <origin
      xyz="0 0 0"
      rpy="0 0 0" />
    <parent
      link="left_shoulder_pitch_link" />
    <child
      link="left_shoulder_roll_link" />
    <axis
      xyz="1 0 0.0" />
    <limit
      lower="-0.17"
      upper="3.01"
      effort="24"
      velocity="20" />
  </joint>
  <link
    name="left_shoulder_yaw_link">
    <inertial>
      <origin xyz="-0.000223 0.000795 -0.127372"  rpy="0 0 0" />
      <mass  value="0.541958" />
      <inertia  ixx="0.001426"  ixy="-0.000028"  ixz="0.000073"  iyy="0.001848"  iyz="-0.000004"  izz="0.000644" />
    </inertial>
    <visual>
      <origin
        xyz="0 0 0"
        rpy="0 0 0" />
      <geometry>
        <mesh
          filename="meshes/arm_l3_link.STL" />
      </geometry>
      <material
        name="">
        <color
          rgba="0.64706 0.61961 0.58824 1" />
      </material>
    </visual>
    <collision>
      <origin
        xyz="0 0 0"
        rpy="0 0 0" />
      <geometry>
        <mesh
          filename="meshes/arm_l3_link.STL" />
      </geometry>
    </collision>
  </link>
  <joint
    name="left_shoulder_yaw_joint"
    type="revolute">
    <origin
      xyz="0 0 -0.1019"
      rpy="0 0 0" />
    <parent
      link="left_shoulder_roll_link" />
    <child
      link="left_shoulder_yaw_link" />
    <axis
      xyz="0 0 1" />
    <limit
      lower="-3.14"
      upper="1.57"
      effort="5"
      velocity="20" />
  </joint>
 <link
    name="left_elbow_link">
    <inertial>
      <origin xyz="0.103629 0.001055 -0.003321"  rpy="0 0 0" />
      <mass  value="0.368568" />
      <inertia  ixx="0.000281"  ixy="0.0000025"  ixz="-0.000126"  iyy="0.002877"  iyz="0.000002"  izz="0.002879" />
    </inertial>
    <visual>
      <origin
        xyz="0 0 0"
        rpy="0 0 0" />
      <geometry>
        <mesh
          filename="meshes/arm_l4_link.STL" />
      </geometry>
      <material
        name="">
        <color
          rgba="0.64706 0.61961 0.58824 1" />
      </material>
    </visual>
    <collision>
      <origin
        xyz="0 0 0"
        rpy="0 0 0" />
      <geometry>
        <mesh
          filename="meshes/arm_l4_link.STL" />
      </geometry>
    </collision>
  </link>
  <joint
    name="left_elbow_joint"
    type="revolute">
    <origin
      xyz="0 -0.0062 -0.1616"
      rpy="0 0 0" />
    <parent
      link="left_shoulder_yaw_link" />
    <child
      link="left_elbow_link" />
    <axis
      xyz="0 1 0" />
    <limit
      lower="-0.9"
      upper="1.57"
      effort="5"
      velocity="20" />
  </joint>

  <link
    name="right_shoulder_pitch_link">
     <inertial>
      <origin  xyz="-0.003672 0.009404 -0.000747"  rpy="0 0 0" />
      <mass  value="0.870023" />
      <inertia ixx="0.001279"  ixy="-0.000030"  ixz="0.000016"  iyy="0.000567"  iyz="-0.000017" izz="0.001006" />
    </inertial>
    <visual>
      <origin
        xyz="0 0 0"
        rpy="0 0 0" />
      <geometry>
        <mesh
          filename="meshes/arm_r1_link.STL" />
      </geometry>
      <material
        name="">
        <color
          rgba="0.64706 0.61961 0.58824 1" />
      </material>
    </visual>
    <!-- <collision>
      <origin
        xyz="0 0 0"
        rpy="0 0 0" />
      <geometry>
        <mesh
          filename="meshes/arm_r1_link.STL" />
      </geometry>
    </collision> -->
  </link>

  <joint
    name="right_shoulder_pitch_joint"
    type="revolute">
    <origin
      xyz="0 -0.25799 0.0"
      rpy="0 0 0" />
    <parent
      link="torso_link" />
    <child
      link="right_shoulder_pitch_link" />
    <axis
      xyz="0 1 0" />
    <limit
      lower="-2.74"
      upper="1.96"
      effort="24"
      velocity="20" />
  </joint>
  <link
    name="right_shoulder_roll_link">
    <inertial>
      <origin xyz="0.004341 -0.000257 -0.056511"  rpy="0 0 0" />
      <mass  value="0.712915" />
      <inertia  ixx="0.001609"  ixy="0.000016"  ixz="-0.000130"  iyy="0.001425"  iyz="0.000013"  izz="0.001160" />
    </inertial>
    <visual>
      <origin
        xyz="0 0 0"
        rpy="0 0 0" />
      <geometry>
        <mesh
          filename="meshes/arm_r2_link.STL" />
      </geometry>
      <material
        name="">
        <color
          rgba="0.64706 0.61961 0.58824 1" />
      </material>
    </visual>
    <!-- <collision>
      <origin
        xyz="0 0 0"
        rpy="0 0 0" />
      <geometry>
        <mesh
          filename="meshes/arm_r2_link.STL" />
      </geometry>
    </collision> -->
  </link>
  <joint
    name="right_shoulder_roll_joint"
    type="revolute">
    <origin
      xyz="0 0 0"
      rpy="0 0 0" />
    <parent
      link="right_shoulder_pitch_link" />
    <child
      link="right_shoulder_roll_link" />
    <axis
      xyz="1 0 0" />
    <limit
      lower="-3.01"
      upper="0.17"
      effort="24"
      velocity="20" />
  </joint>
  <link
    name="right_shoulder_yaw_link">
    <inertial>
      <origin xyz="-0.000140 -0.000801 -0.127387"  rpy="0 0 0" />
      <mass  value="0.541111" />
      <inertia  ixx="0.001408"  ixy="0.000026"  ixz="0.000001"  iyy="0.001836"  iyz="0.000016"  izz="0.000643" />
    </inertial>
    <visual>
      <origin
        xyz="0 0 0"
        rpy="0 0 0" />
      <geometry>
        <mesh
          filename="meshes/arm_r3_link.STL" />
      </geometry>
      <material
        name="">
        <color
          rgba="0.64706 0.61961 0.58824 1" />
      </material>
    </visual>
    <collision>
      <origin
        xyz="0 0 0"
        rpy="0 0 0" />
      <geometry>
        <mesh
          filename="meshes/arm_r3_link.STL" />
      </geometry>
    </collision>
  </link>
  <joint
    name="right_shoulder_yaw_joint"
    type="revolute">
    <origin
      xyz="0 0 -0.1019"
      rpy="0 0 0" />
    <parent
      link="right_shoulder_roll_link" />
    <child
      link="right_shoulder_yaw_link" />
    <axis
      xyz="0 0 1" />
    <limit
      lower="-1.57"
      upper="3.14"
      effort="5"
      velocity="20" />
  </joint>
 <link
    name="right_elbow_link">
    <inertial>
      <origin xyz="0.103611 -0.001052 -0.003324"  rpy="0 0 0" />
      <mass  value="0.368568" />
      <inertia  ixx="0.000281"  ixy="-0.0000025"  ixz="-0.000126"  iyy="0.002878"  iyz="-0.000002"  izz="0.002879" />
    </inertial>
    <visual>
      <origin
        xyz="0 0 0"
        rpy="0 0 0" />
      <geometry>
        <mesh
          filename="meshes/arm_r4_link.STL" />
      </geometry>
      <material
        name="">
        <color
          rgba="0.64706 0.61961 0.58824 1" />
      </material>
    </visual>
    <collision>
      <origin
        xyz="0 0 0"
        rpy="0 0 0" />
      <geometry>
        <mesh
          filename="meshes/arm_r4_link.STL" />
      </geometry>
    </collision>
  </link>
  <joint name="right_elbow_joint"  type="revolute">
    <origin
      xyz="0 0.0062 -0.1616"
      rpy="0 0 0" />
    <parent
      link="right_shoulder_yaw_link" />
    <child
      link="right_elbow_link" />
    <axis
      xyz="0 1 0" />
    <limit
      lower="-0.9"
      upper="1.57"
      effort="5"
      velocity="20" />
  </joint>
</robot>